Workbook

Sheet Energie_EBF
B1: Energieauswertung
B2: Projektnummer und Objekt
B3: Baujahr | J3: Berechnung Heizleistungsbedarf Wohnbauten
B5: Elektro Allg. | J5: Klimaregion | K5: Zürich-MeteoSchweiz
C6: Verbrauch HT | D6: Verbrauch NT | E6: Verbrauch | J6: Gebäudekategorie | K6: EFH
B7: Jahr | E7: kWh | J7: Energiebezugsfläche (EBF) | K7: =C34 -> 100 | L7: m2
J9: Warmwasser über Heizung | K9: Ja
J10: Volllaststunden | K10: 2700 | L10: h
J11: Wirkungsgrad bestehende Wärmeerzeugung | K11: 0.9 | L11: [-]
J12: Mittelwert Energieverbrauch | K12: =D24 -> 10000 | L12: kWh
B13: Mittelwert | E13: =AVERAGE(E8:E12) -> #DIV/0! | J13: Energiekennzahl | K13: =K12/K7 -> 100 | L13: kWh/m2
B14: kWh/m2 | E14: =E13/C34 -> #DIV/0!
J15: Nutzwärmebedarf | K15: =K12*K11 -> 9000 | L15: kWh
B16: Gas bzw. Öl | J16: Heizleistung | K16: =ROUND(K15/K10,1) -> 3.3 | L16: kW
C17: Verbrauch | D17: Verbrauch | J17: spezifische Heizleistung | K17: =K16/K7*1000 -> 33 | L17: W/m2
B18: Jahr | C18: l bzw. m3 | D18: kWh
B19: Test | C19: 1000 | D19: =C19*B29 -> 10000 | J19: Reserve | K19: 0.1
J20: Heizleistung mit Reserve | K20: =ROUND(K16*K19+K16,1) -> 3.6 | L20: kW
J22: Zuschlag für 2x 2h Sperrung EW (Faktor 1.2)* | K22: 0.2 | M22: *beim EKZ Gebiet erst ab 4 kW Kompressorleistung (rund 15 kW WP)
J23: Heizleistung neue Anlage | K23: =ROUND(K20*K22+K20,1) -> 4.3 | L23: kW
B24: Mittelwert | C24: =AVERAGE(C19:C23) -> 1000 | D24: =AVERAGE(D19:D23) -> 10000
B25: kWh/m2 | D25: =D24/C34 -> 100
J26: Erdwärmesonde (EWS)
B27: Umrechnungsfaktor | J27: spezifische Entnahmeleistung | K27: 35 | L27: W/m
B28: Heizwert Gas bzw. Öl | J28: Bezug aus Erdreich | K28: 0.75
B29: 10 | J29: Tiefe Erdwärmesonde total | K29: =K23/K27*K28*1000 -> 92.142857 | L29: m
B31: Flächen | J31: Anzahl Erdwärmesonden | K31: 1 | L31: [Stück]
C32: EBF | J32: Tiefe Erdwärmesonde pro Sonde | K32: =K29/K31 -> 92.142857 | L32: m
B33: Stockwerk | C33: m2
B34: Total EBF | C34: =Tabelle315[[#Totals],[Fläche Total]] -> 100
B37: Kalt-Wasser [m3]
C38: Verbrauch | F38: Datum | G38: Restbestand | H38: Lieferung
B39: Jahr | C39: m3
B45: Mittelwert | C45: =AVERAGE(C40:C44) -> #DIV/0!
B46: m3/m2 | C46: =C45/C34 -> #DIV/0!
E50: Total | I50: Tage; l; l
E51: Jahre | F51: =F50/365 -> 0 | I51: Jahr
E52: Verbrauch Total | H52: =H50+G50 -> 0 | I52: l
E53: Verbrauch pro Jahr | H53: =H52/F51 -> #DIV/0! | I53: l/a

Sheet Flächen
B1: Zusammenstellung der Gebäudehülle
B3: Bauteil Nr. | C3: Ausrichtung | D3: Beschrieb | E3: Länge / Umfang | F3: Breite / Höhe | G3: Fläche | H3: Anzahl | I3: Fläche Total | J3: Fläche Neu | K3: Anzahl Neu | L3: Fläche Total Neu | M3: Beschrieb Neu
E4: [m] | G4: [m2] | H4: [Stk.] | I4: [m2] | J4: [m2] | K4: [Stk.] | L4: [m2]
B5: =Energie_EBF!K23 -> 4.3
B6: EBF | C6: Ausrichtung | D6: Beschrieb | E6: Länge | F6: Breite | G6: Fläche | H6: Anzahl | I6: Fläche Total | J6: Fläche Neu | K6: Anzahl Neu | L6: Fläche Total Neu | M6: Beschrieb Neu | O6: Kontrolle | R6: Kontrolle Fassaden | U6: EBF | V6: Berechnung Dach
B7: 1 | C7: UG | G7: 0 | H7: =1 -> 1 | I7: =G7*H7 -> 0 | O7: Dach | P7: =SUM(I19,I26) -> 0 | R7: N | S7: =SUMIF(C28:G47,R7,G28:G47) -> 0 | U7: Dach gegen Aussenluft | V7: N/O/S/W | Y7: N/O/S/W
B8: 2 | C8: EG | D8: Test | G8: 100 | H8: =1 -> 1 | I8: =G8*H8 -> 100 | O8: Boden | P8: =SUM(I62,I69,I76) -> 0 | R8: S | S8: =SUMIF(C28:G47,R8,G28:G47) -> 0
B9: 3 | C9: 1. OG | G9: =Tabelle315[[#This Row],[Länge]]*Tabelle315[[#This Row],[Breite]] -> 0 | H9: =1 -> 1 | I9: =G9*H9 -> 0 | O9: EBF | P9: =I12 -> 100
B10: 4 | C10: 2. OG | G10: =Tabelle315[[#This Row],[Länge]]*Tabelle315[[#This Row],[Breite]] -> 0 | H10: =1 -> 1 | I10: =G10*H10 -> 0 | R10: O | S10: =SUMIF(C28:G47,R10,G28:G47) -> 0
B11: 5 | C11: DG | G11: =Tabelle315[[#This Row],[Länge]]*Tabelle315[[#This Row],[Breite]] -> 0 | H11: =1 -> 1 | I11: =G11*H11 -> 0 | R11: W | S11: =SUMIF(C28:G47,R11,G28:G47) -> 0 | V11: Total | W11: =SUM(W7:W10) -> 0 | Y11: Total | Z11: =SUM(Z7:Z10) -> 0
B12: total EBF | H12: =SUBTOTAL(109,Tabelle315[Anzahl]) -> 5 | I12: =SUBTOTAL(109,Tabelle315[Fläche Total]) -> 100 | K12: =SUBTOTAL(109,Tabelle315[Anzahl Neu]) -> 0 | L12: =SUBTOTAL(109,Tabelle315[Fläche Total Neu]) -> 0 | U12: Wand gegen unbeheizt
B13: Dach gegen Aussenluft | C13: Ausrichtung | D13: Beschrieb | E13: Länge | F13: Breite | G13: Fläche | H13: Anzahl | I13: Fläche Total | J13: Fläche Neu | K13: Anzahl Neu | L13: Fläche Total Neu | M13: Beschrieb Neu | U13: Fenster und Türen
B14: 1 | G14: =E14*F14 -> 0 | H14: =1 -> 1 | I14: =G14*H14 -> 0 | U14: Boden gegen Erdreich
B15: 2 | G15: =E15*F15 -> 0 | H15: =1 -> 1 | I15: =G15*H15 -> 0
B16: 3 | G16: =E16*F16 -> 0 | H16: =1 -> 1 | I16: =G16*H16 -> 0
B17: 4 | G17: =E17*F17 -> 0 | H17: =1 -> 1 | I17: =G17*H17 -> 0
B18: 5 | G18: =E18*F18 -> 0 | H18: =1 -> 1 | I18: =G18*H18 -> 0
H19: =SUBTOTAL(109,Tabelle3[Anzahl]) -> 5 | I19: =SUBTOTAL(109,Tabelle3[Fläche Total]) -> 0 | K19: =SUBTOTAL(109,Tabelle3[Anzahl Neu]) -> 0 | L19: =SUBTOTAL(109,Tabelle3[Fläche Total Neu]) -> 0 | U19: Boden gegen unbeheizt
B20: Decke gegen unbeheizt | C20: Ausrichtung | D20: Beschrieb | E20: Länge | F20: Breite | G20: Fläche | H20: Anzahl | I20: Fläche Total | J20: Fläche Neu | K20: Anzahl Neu | L20: Fläche Total Neu | M20: Beschrieb Neu | U20: Boden gegen aussen
B21: 1 | G21: =E21*F21 -> 0 | H21: =1 -> 1 | I21: =G21*H21 -> 0
B22: 2 | G22: =E22*F22 -> 0 | H22: =1 -> 1 | I22: =G22*H22 -> 0
B23: 3 | G23: =E23*F23 -> 0 | H23: =1 -> 1 | I23: =G23*H23 -> 0 | O23: Benutzung (Reihenfolge Tabellen entspricht Reigenfolge GEAK-Tool) Mit tab in Eingabezeile der Tabelle bis ans ENDE --> macht neue Zeile mit gleichem Format und Formeln Die Letzte Zeile vom Bauteil ist die Ergebniszeile und Zeigt die Summe der Fläche total und die Summe der Anzahl (z.B Anzahl Fenster). | X23: Dachfläche anhand Grundfläche und Dachneigung | AC23: Dachneigung Berechnen mit Höhe
B24: 4 | G24: =E24*F24 -> 0 | H24: =1 -> 1 | I24: =G24*H24 -> 0
B25: 5 | G25: =E25*F25 -> 0 | H25: =1 -> 1 | I25: =G25*H25 -> 0
H26: =SUBTOTAL(109,Tabelle438[Anzahl]) -> 5 | I26: =SUBTOTAL(109,Tabelle438[Fläche Total]) -> 0 | K26: =SUBTOTAL(109,Tabelle438[Anzahl Neu]) -> 0 | L26: =SUBTOTAL(109,Tabelle438[Fläche Total Neu]) -> 0
B27: Wand gegen Aussenluft | C27: Ausrichtung | D27: Beschrieb | E27: Länge | F27: Höhe | G27: Fläche | H27: Anzahl | I27: Fläche Total | J27: Fläche Neu | K27: Anzahl Neu | L27: Fläche Total Neu | M27: Beschrieb Neu
B28: 1 | G28: 0 | H28: =1 -> 1 | I28: =G28*H28 -> 0 | X28: Grundfläche [m2] | Y28: 100 | AC28: Höhe | AD28: 15
B29: 2 | G29: 0 | H29: =1 -> 1 | I29: =G29*H29 -> 0 | X29: Dachneigung [°] | Y29: 45 | AC29: Breite | AD29: 30
B30: 3 | G30: 0 | H30: =1 -> 1 | I30: =G30*H30 -> 0
B31: 4 | G31: 0 | H31: =1 -> 1 | I31: =G31*H31 -> 0
B32: 5 | G32: 0 | H32: =1 -> 1 | I32: =G32*H32 -> 0
H33: =SUBTOTAL(109,Tabelle4[Anzahl]) -> 5 | I33: =SUBTOTAL(109,Tabelle4[Fläche Total]) -> 0 | K33: =SUBTOTAL(109,Tabelle4[Anzahl Neu]) -> 0 | L33: =SUBTOTAL(109,Tabelle4[Fläche Total Neu]) -> 0 | O33: neue Flächen - wenn Fenster abgerissen werden, gleiche Fläche bei Fläche neu mit minus eintragen - wenn neue Fenster eingebaut, bei alt Anzahl null und dann bei neu bsp. 1 eintragen
B34: Wand gegen Erdreich | C34: Ausrichtung | D34: Beschrieb | E34: Länge | F34: Höhe | G34: Fläche | H34: Anzahl | I34: Fläche Total | J34: Fläche Neu | K34: Anzahl Neu | L34: Fläche Total Neu | M34: Beschrieb Neu
B35: 1 | G35: =E35*F35 -> 0 | H35: 1 | I35: =G35*H35 -> 0
B36: 2 | G36: =E36*F36 -> 0 | H36: 1 | I36: =G36*H36 -> 0 | X36: Dachfläche total [m2] | Y36: =Y28/(COS((RADIANS(Y29)))) -> 141.42136 | AC36: Dachneigung [°] | AD36: =DEGREES(ATAN(AD28/(AD29/2))) -> 45
B37: 3 | G37: =E37*F37 -> 0 | H37: 1 | I37: =G37*H37 -> 0
B38: 4 | G38: =E38*F38 -> 0 | H38: 1 | I38: =G38*H38 -> 0 | X38: Faktor | Y38: =Y36/Y28 -> 1.4142136
B39: 5 | G39: =E39*F39 -> 0 | H39: 1 | I39: =G39*H39 -> 0
H40: =SUBTOTAL(109,Tabelle5[Anzahl]) -> 5 | I40: =SUBTOTAL(109,Tabelle5[Fläche Total]) -> 0 | K40: =SUBTOTAL(109,Tabelle5[Anzahl Neu]) -> 0 | L40: =SUBTOTAL(109,Tabelle5[Fläche Total Neu]) -> 0
B41: Wand gegen unbeheizt | C41: Ausrichtung | D41: Beschrieb | E41: Länge | F41: Höhe | G41: Fläche | H41: Anzahl | I41: Fläche Total | J41: Fläche Neu | K41: Anzahl Neu | L41: Fläche Total Neu | M41: Beschrieb Neu
...

Sheet U-Werte
B2: Baumaterialien | H2: Dämm-Materialien | P2: b-Faktoren | U2: Auswahlfelder
B3: Bau-Material | C3: Aerogel, Agitech Spaceloft | E3: 0.015 | F3: Weiter U-Werte in | H3: Dämm-Material | I3: Kork/Korkschrottmatte | K3: 0.056 | P3: Estrichraum, Schrägdach ungedämmt | R3: 0.9 | U3: Kellerboden | V3: Wärmeübergang gegen Erdreich
C4: Ziegel | E4: 0.8 | I4: Wärmedämmung, Prod. Unbekannt (bspw. Styropor bzw. EPS) | K4: 0.038 | P4: Estrichraum, Schrägdach gedämmt U<0.4 | R4: 0.7 | U4: Kellerwand gg. Aussen | V4: Wärmeübergang gegen aussen | W4: 1 | X4: 25 | Y4: =W4/X4 -> 0.04
C5: Bollenstein, ab ca. 50 cm dick | E5: 0.9 | I5: Schlacke | K5: 0.35 | P5: Kellerraum ganz im Erdreich | R5: 0.7 | U5: Kellerwand gg. Erdreich | V5: Wärmeübergang gegen Erdreich
C6: Stahlbeton, 1% Stahl / Steinbodenplatten | E6: 2.3 | H6: Aussen-wand | I6: Flumroc COMPACT PRO, Fassade | K6: 0.033 | P6: Kellerraum teilweise oder ganz über dem Erdreich | R6: 0.8 | U6: Kellerwand gg. Unbeheizt | V6: Wärmeübergang gegen Unbeheizt | W6: 1 | X6: 8 | Y6: =W6/X6 -> 0.125
C7: Backstein (Einsteinmauerwerk) | E7: 0.44 | I7: Swisspor Lamda White 031, EPS | K7: 0.031 | P7: angebauter Raum | R7: 0.8 | U7: Keller-Decke | V7: Wärmeübergang gegen Unbeheizt | W7: 1 | X7: 8 | Y7: =W7/X7 -> 0.125
C8: Backstein (Verbandmrwk) d=28-30 | E8: 0.37 | I8: Multipor Innendämmung | K8: 0.042 | P8: Glasvorbau | R8: 0.9 | U8: Aussenwand | V8: Wärmeübergang gegen aussen | W8: 1 | X8: 25 | Y8: =W8/X8 -> 0.04
C9: Kalksandstein | E9: 0.8 | I9: SwissporXPS Premium Plus 300 | K9: 0.027 | U9: Boden gg. Aussen | V9: Wärmeübergang gegen aussen | W9: 1 | X9: 25 | Y9: =W9/X9 -> 0.04
C10: Schilf (alte Gebäude) | E10: 0.065
C11: Hourdisdecke komlett (gemäss Abbildung) | D11: U-Wert 0.9 | F11: Tabellenblatt | I11: Foamglas T4+ | K11: 0.041 | P11: Kellerboden im Erdreich | R11: 0.3 | U11: Storenabdeckung mit Aerogel | V11: Wärmeübergang gegen aussen | W11: 1 | X11: 25 | Y11: =W11/X11 -> 0.04
C12: Aussenputz | E12: 0.87 | F12: Bauteilkatalog | H12: Dach | I12: Flumroc Solo, 15% Holzanteil (innen wenig Sparren) | K12: =0.035*0.88+0.14*0.12 -> 0.0476 | U12: Estrichboden | V12: Wärmeübergang gegen Unbeheizt | W12: 1 | X12: 8 | Y12: =W12/X12 -> 0.125
C13: Innenputz | E13: 0.7 | I13: Gutex Dämmplatte DW+ | K13: 0.042 | U13: Steildach | V13: äusserer Übergang bei Hinterlüftung = 1/12.5 | W13: 1 | X13: 8 | Y13: =W13/X13 -> 0.125
C14: Holz | E14: 0.14 | I14: Isofloc oder bestehend, 15% Holzanteil (Standard) | K14: =0.038*0.88+0.14*0.12 -> 0.05024 | U14: Flachdach | V14: Wärmeübergang gegen aussen | W14: 1 | X14: 25 | Y14: =W14/X14 -> 0.04
C15: Tonhourdis (Kellerdecke) | E15: 0.44 | I15: SwissporLAMDA Roof | K15: 0.029
C16: Holzbalkendecke komplett (gemäss Abbildung) | D16: U-Wert 0.8 | I16: PU-Dämm. für Flachdach/Terrasse/Boden, Vlies | K16: 0.026
C17: Unterlagsboden | E17: 1.4 | H17: UG-Decke | I17: Thermo-Plus, Glaswolle, Kellerdecke | K17: 0.031 | U17: Fassadendämmung | V17: Flumroc COMPACT PRO | X17: 0.034
C18: Gipskartonplatte | E18: 0.21 | I18: Flumroc-Dämmplatte 3, 15% Holzanteil (innen wenig Sparren) | K18: =0.033/0.85 -> 0.038823529 | U18: Kellerdecke | V18: Thermo-Plus, Glaswolle | X18: 0.031
C19: Heraklith, Holzwolle (HWL) Zementgebunden, Perfecta | E19: 0.095 | H19: Innenwand | I19: WILAN 3, mit einseitiger Fertigdeckschicht | K19: 0.031 | U19: Flachdach/Terasse | V19: PU-Dämmung, Vlies | X19: 0.026
I20: Swisspor Lamda White 031, EPS | K20: 0.031 | U20: Innendämmung | V20: Multipor Innendämmung | X20: 0.042
I21: Foamglas T3+ | K21: 0.036
H22: DG-Boden | I22: Flumroc-Dämmplatte 3 m. 15% Holzanteil | K22: =0.033/0.85 -> 0.038823529
I23: Flumroc ESTRA, Estrichbodenplatte | K23: 0.034 | P23: äusserer Übergang bei Hinterlüftung = 1/12.5 = 0.08
B27: U-Wert-Berechnung IST | D27: Beschrieb Bauteil | H27: U-Wert-Berechnung SOLL | N27: Benutzung: Erste 4 U-Wert Kästen sind zum Einfüllen, für weitere einfach Ist und Soll miteinander kopieren U-Wert Berechnung IST 1) im Hellgelben Feld per Dropdown Bauteil auswählen ( èbergangsfakrot wird automatisch ausgewählt) 2) bei Bedarf im knallgelben Feld eine Beschreibung für das Bauteil einfügen z.B Aussenwand EG 3) b-Faktor per Dropdown auswählen oder überschreiben U-Wert Berechnung SOLL Alle eingefüllten Werte vom Ist-Zustand werden übernommen 4) im hellgelben Feld die Art der Dämmung auswählen, Werte für typische Lambdawerte werden übernommen, sonst überschreiben 5) Dimension Wärmedämmung (d in m) für gewünschten U-Wert ermitteln | V27: Fenster | AE27: U-Wert Tabelle nach Baualtersklassen | AN27: U-Werte Fenster nach Baualterklassen
F28: W/m2K | H28: =B28 -> 0 | J28: =D28 -> 0 | L28: W/m2K | V28: alter | W28: Beschrieb | X28: Anzahl Gläser | Y28: Rahmen | Z28: Wärmeschutz (Ja/Nein) | AA28: U-Wert
B29: Nr. | C29: Was | D29: d in m | E29: λ | F29: d/λ (R ) | H29: Nr. | I29: Was | J29: d in m | K29: λ | L29: d/λ (R ) | T29: bsp. | V29: 1980 | W29: alle Fenster Hauptgebäude | X29: 2 | Y29: Holz | Z29: Nein | AA29: 2.7
B30: 1 | C30: Wärmeübergang Innen | D30: 1 | E30: 8 | F30: =IFERROR(D30/E30,"-") -> 0.125 | H30: 1 | I30: Wärmeübergang Innen | J30: 1 | K30: 8 | L30: =IFERROR(J30/K30,"-") -> 0.125
B31: 2 | F31: =IFERROR(D31/E31,"-") -> - | H31: 2 | I31: =C31 -> 0 | J31: =D31 -> 0 | K31: =E31 -> 0 | L31: =IFERROR(J31/K31,"-") -> -
B32: 3 | F32: =IFERROR(D32/E32,"-") -> - | H32: 3 | I32: =C32 -> 0 | J32: =D32 -> 0 | K32: =E32 -> 0 | L32: =IFERROR(J32/K32,"-") -> -
B33: 4 | F33: =IFERROR(D33/E33,"-") -> - | H33: 4 | I33: =C33 -> 0 | J33: =D33 -> 0 | K33: =E33 -> 0 | L33: =IFERROR(J33/K33,"-") -> -
B34: 5 | F34: =IFERROR(D34/E34,"-") -> - | H34: 5 | I34: =C34 -> 0 | J34: =D34 -> 0 | K34: =E34 -> 0 | L34: =IFERROR(J34/K34,"-") -> -
B35: 6 | F35: =IFERROR(D35/E35,"-") -> - | H35: 6 | I35: =C35 -> 0 | J35: =D35 -> 0 | K35: =E35 -> 0 | L35: =IFERROR(J35/K35,"-") -> -
B36: 7 | F36: =IFERROR(D36/E36,"-") -> - | H36: 7 | I36: =C36 -> 0 | J36: =D36 -> 0 | K36: =E36 -> 0 | L36: =IFERROR(J36/K36,"-") -> -
B37: 8 | F37: =IFERROR(D37/E37,"-") -> - | H37: 8 | J37: 0.1 | K37: =VLOOKUP(I37,$I$3:$K$23,3,FALSE) -> #N/A | L37: =IFERROR(J37/K37,"-") -> -
B38: 9 | C38: =VLOOKUP(B28,$U$3:$X$14,2,FALSE) -> #N/A | D38: =VLOOKUP(B28,$U$3:$X$14,3,FALSE) -> #N/A | E38: =VLOOKUP(B28,$U$3:$X$14,4,FALSE) -> #N/A | F38: =IFERROR(D38/E38,"-") -> - | H38: 9 | I38: =C38 -> #N/A | J38: =D38 -> #N/A | K38: =E38 -> #N/A | L38: =IFERROR(J38/K38,"-") -> -
E39: R total = | F39: =SUM(F30:F38) -> 0.125 | K39: R total = | L39: =SUM(L30:L38) -> 0.125
B40: b-Faktor | E40: U-Wert (ohne b-Faktor) = | F40: =1/F39 -> 8 | H40: b-Faktor | K40: U-Wert (ohne b-Faktor) = | L40: =1/L39 -> 8
E41: U-Wert (mit b-Faktor) = | F41: =B41*F40 -> 0 | H41: =B41 -> 0 | K41: U-Wert (mit b-Faktor) = | L41: =H41*L40 -> 0
F42: W/m2K | L42: W/m2K
B44: U-Wert-Berechnung IST | D44: Beschrieb Bauteil | H44: U-Wert-Berechnung SOLL | P44: U-Wert-Berechnung IST | R44: Beschrieb Bauteil | V44: U-Wert-Berechnung SOLL
F45: W/m2K | H45: =B45 -> 0 | J45: =D45 -> 0 | L45: W/m2K | T45: W/m2K | V45: =P45 -> 0 | X45: =R45 -> 0 | Z45: W/m2K
...

Sheet Kosten HLK
B2: Investitionskosten Heizung | E2: Gelbe Felder bearbeiten
B4: Investitionskosten | G4: Fördergelder
B5: =Energie_EBF!K23 -> 4.3 | C5: kW (Wärmepumpe inkl. allfälliger Sperrzeiten) | G5: Kanton Zürich | H5: zusätzlich Stadt Zürich* | S5: **Energiezukunft Schweiz | U5: * dazu kommt die Restwertentschädigung
B6: =ROUND(45000+IF(B5>5,2100*(B5-5),0),-3) -> 45000 | C6: Kosten Wärmepumpe Luft | G6: =2900+IF(B5>15,(B5-15)*160,0) -> 2900 | H6: =ROUND(8000+B5*120,-2)-G6 -> 5600 | S6: =ROUND(S9*S10,-2) -> 1800 | U6: ** Ab April 2023 bei Eigenbedarf nur Wärmepumpen grösser als 50 kW, keine Einschränkungen für Wärmepumpen in Mietliegenschaften.
B7: =ROUND(55000+IF(B5>5,3200*(B5-5),0),-3) -> 55000 | C7: Kosten Wärmepumpe Erdsonde | G7: =6800+IF(B5>15,(B5-15)*420,0) -> 6800 | H7: =ROUND(16000+360*B5,-2)-G7 -> 10700 | S7: =ROUND(S9*S10,-2) -> 1800 | U7: Holzheizungen und grössere Anlagen (ca. > 30 kW)
B8: =Energie_EBF!K20 -> 3.6 | C8: kW (Fossil oder Fernwärme ohne Sperrzeiten) | G8: Stadt Zürich zusätzlich Restwertentschädigung (bis 25 Jahre) | U8: https://energiezukunftschweiz.ch/de/foerderprogramme/angebot/klimapraemie-heizungsersatz/
B9: =ROUND(15000+IF(B8>10,500*(B8-10),0),-3) -> 15000 | C9: Kosten Ölheizung | G9: Energieverbrauch (kWh) | S9: =Energie_EBF!K12 -> 10000 | U9: Stadt Zürich
B10: =ROUND(12000+IF(B8>10,500*(B8-10),0),-3) -> 12000 | C10: Kosten Gasheizung | G10: Fördergelder (CHF/kWh) | S10: 0.18 | U10: https://rechner.energie-foerderung.ch/zs
B11: =ROUND(45000+IF(B8>10,1200*(B8-10),0),-3) -> 45000 | C11: Kosten Pelletheizung
B12: =ROUND((25900+20000)+IF(B8>50,(B8-50)*(230+20),0),-3) -> 46000 | C12: Kosten Fernwärme (Kontrolle mit Preise Tabelle) | G12: =5200+IF(B8>15,(B8-15)*100,0) -> 5200 | H12: =ROUND(12000+B8*120,-2)-G12 -> 7200 | S12: =ROUND(S10*S9,-2) -> 1800
B14: zusätzliche Kosten:
B15: viel Grabarbeiten (ca. 3-10'000.-), aufwändige Demontagen (ca. 2'000.-), sehr kleine Leistung aber Aufwändig (3'000.-), Tankrückbau inkl. Tür (4-5000.-), Gasanschluss Rückbau in Strasse (3-5'000.-), Kühlung (5'000.- /Whg.)
B18: Investitionskosten Lüftung | S18: Investitionskosten Solarthermie
I19: Komfortlüftung inkl. minimalen bauliche Kosten
B20: Anzahl Wohnungen und Wohnungsgrösse | J20: 0 | K20: 0 | L20: 0 | M20: 1 | N20: 2 | O20: 3 | Q20: Wohnungsgrössen | S20: Anzahl Personen
B21: 1 | C21: Wohnungstyp 1 | D21: 4 | E21: Zi- Wohnung | G21: =_xlfn.IFNA(INDEX($I$21:$O$51,B21+2,D21+1),"-") -> 27000 | I21: Anzahl Wohnungen | J21: 1.5 | K21: 2.5 | L21: 3.5 | M21: 4.5 | N21: 5.5 | O21: 6.5 | S21: 4 | T21: Personen
C22: Wohnungstyp 2 | E22: Zi- Wohnung | G22: =_xlfn.IFNA(INDEX($I$21:$O$51,B22+2,D22+1),"-") -> 0 | Q22: 1.5
C23: Wohnungstyp 3 | E23: Zi- Wohnung | G23: =_xlfn.IFNA(INDEX($I$21:$O$51,B23+2,D23+1),"-") -> 0 | I23: 1 | J23: 10000 | K23: 15000 | L23: 25000 | M23: =$L23+($I23*M$20*2000) -> 27000 | N23: =$L23+($I23*N$20*2000) -> 29000 | O23: =$L23+($I23*O$20*2000) -> 31000 | Q23: 2 | S23: 15000 | T23: Grundkosten (EFH, 2-4 Personen)
C24: Wohnungstyp 4 | E24: Zi- Wohnung | G24: =_xlfn.IFNA(INDEX($I$21:$O$51,B24+2,D24+1),"-") -> 0 | I24: 2 | J24: =ROUND(J23+$J$23,-3) -> 20000 | K24: =ROUND(K23+$K$23,-3) -> 30000 | L24: =ROUND(L23+$L$23,-3) -> 50000 | M24: =ROUND(M23+$M$23,-3) -> 54000 | N24: =ROUND(N23+$N$23,-3) -> 58000 | O24: =ROUND(O23+$O$23,-3) -> 62000 | Q24: 2.5 | S24: =(S21-4)*1250 -> 0 | T24: weniger bzw. mehr Person
C25: Wohnungstyp 5 | E25: Zi- Wohnung | G25: =_xlfn.IFNA(INDEX($I$21:$O$51,B25+2,D25+1),"-") -> 0 | I25: 3 | J25: =ROUND(J24+$J$23,-3) -> 30000 | K25: =ROUND(K24+$K$23,-3) -> 45000 | L25: =ROUND(L24+$L$23,-3) -> 75000 | M25: =ROUND(M24+$M$23,-3) -> 81000 | N25: =ROUND(N24+$N$23,-3) -> 87000 | O25: =ROUND(O24+$O$23,-3) -> 93000 | Q25: 3 | S25: =SUM(S23:S24) -> 15000 | T25: Kosten Total
B26: Zwischentotal | G26: =SUM(G21:G25) -> 27000 | I26: 4 | J26: =ROUND(J25+$J$23,-3) -> 40000 | K26: =ROUND(K25+$K$23,-3) -> 60000 | L26: =ROUND(L25+$L$23,-3) -> 100000 | M26: =ROUND(M25+$M$23,-3) -> 108000 | N26: =ROUND(N25+$N$23,-3) -> 116000 | O26: =ROUND(O25+$O$23,-3) -> 124000 | Q26: 3.5
B27: Rabatt | C27: =VLOOKUP(B28,Q35:R94,2,2) -> 0 | G27: =G26*C27*-1 -> 0 | I27: 5 | J27: =ROUND(J26+$J$23,-3) -> 50000 | K27: =ROUND(K26+$K$23,-3) -> 75000 | L27: =ROUND(L26+$L$23,-3) -> 125000 | M27: =ROUND(M26+$M$23,-3) -> 135000 | N27: =ROUND(N26+$N$23,-3) -> 145000 | O27: =ROUND(O26+$O$23,-3) -> 155000 | Q27: 4
B28: =SUM(B21:B27) -> 1 | C28: Wohnungen mit totalen Lüftungskosten von | G28: =ROUND(SUM(G26:G27),-3) -> 27000 | I28: 6 | J28: =ROUND(J27+$J$23,-3) -> 60000 | K28: =ROUND(K27+$K$23,-3) -> 90000 | L28: =ROUND(L27+$L$23,-3) -> 150000 | M28: =ROUND(M27+$M$23,-3) -> 162000 | N28: =ROUND(N27+$N$23,-3) -> 174000 | O28: =ROUND(O27+$O$23,-3) -> 186000 | Q28: 4.5
I29: 7 | J29: =ROUND(J28+$J$23,-3) -> 70000 | K29: =ROUND(K28+$K$23,-3) -> 105000 | L29: =ROUND(L28+$L$23,-3) -> 175000 | M29: =ROUND(M28+$M$23,-3) -> 189000 | N29: =ROUND(N28+$N$23,-3) -> 203000 | O29: =ROUND(O28+$O$23,-3) -> 217000 | Q29: 5
I30: 8 | J30: =ROUND(J29+$J$23,-3) -> 80000 | K30: =ROUND(K29+$K$23,-3) -> 120000 | L30: =ROUND(L29+$L$23,-3) -> 200000 | M30: =ROUND(M29+$M$23,-3) -> 216000 | N30: =ROUND(N29+$N$23,-3) -> 232000 | O30: =ROUND(O29+$O$23,-3) -> 248000 | Q30: 5.5
I31: 9 | J31: =ROUND(J30+$J$23,-3) -> 90000 | K31: =ROUND(K30+$K$23,-3) -> 135000 | L31: =ROUND(L30+$L$23,-3) -> 225000 | M31: =ROUND(M30+$M$23,-3) -> 243000 | N31: =ROUND(N30+$N$23,-3) -> 261000 | O31: =ROUND(O30+$O$23,-3) -> 279000 | Q31: 6
I32: 10 | J32: =ROUND(J31+$J$23,-3) -> 100000 | K32: =ROUND(K31+$K$23,-3) -> 150000 | L32: =ROUND(L31+$L$23,-3) -> 250000 | M32: =ROUND(M31+$M$23,-3) -> 270000 | N32: =ROUND(N31+$N$23,-3) -> 290000 | O32: =ROUND(O31+$O$23,-3) -> 310000 | Q32: 6.5
I33: 11 | J33: =ROUND(J32+$J$23,-3) -> 110000 | K33: =ROUND(K32+$K$23,-3) -> 165000 | L33: =ROUND(L32+$L$23,-3) -> 275000 | M33: =ROUND(M32+$M$23,-3) -> 297000 | N33: =ROUND(N32+$N$23,-3) -> 319000 | O33: =ROUND(O32+$O$23,-3) -> 341000
I34: 12 | J34: =ROUND(J33+$J$23,-3) -> 120000 | K34: =ROUND(K33+$K$23,-3) -> 180000 | L34: =ROUND(L33+$L$23,-3) -> 300000 | M34: =ROUND(M33+$M$23,-3) -> 324000 | N34: =ROUND(N33+$N$23,-3) -> 348000 | O34: =ROUND(O33+$O$23,-3) -> 372000
I35: 13 | J35: =ROUND(J34+$J$23,-3) -> 130000 | K35: =ROUND(K34+$K$23,-3) -> 195000 | L35: =ROUND(L34+$L$23,-3) -> 325000 | M35: =ROUND(M34+$M$23,-3) -> 351000 | N35: =ROUND(N34+$N$23,-3) -> 377000 | O35: =ROUND(O34+$O$23,-3) -> 403000 | Q35: Wohnungen | R35: Rabatt
I36: 14 | J36: =ROUND(J35+$J$23,-3) -> 140000 | K36: =ROUND(K35+$K$23,-3) -> 210000 | L36: =ROUND(L35+$L$23,-3) -> 350000 | M36: =ROUND(M35+$M$23,-3) -> 378000 | N36: =ROUND(N35+$N$23,-3) -> 406000 | O36: =ROUND(O35+$O$23,-3) -> 434000 | Q36: 1
I37: 15 | J37: =ROUND(J36+$J$23,-3) -> 150000 | K37: =ROUND(K36+$K$23,-3) -> 225000 | L37: =ROUND(L36+$L$23,-3) -> 375000 | M37: =ROUND(M36+$M$23,-3) -> 405000 | N37: =ROUND(N36+$N$23,-3) -> 435000 | O37: =ROUND(O36+$O$23,-3) -> 465000 | Q37: 2 | R37: 0.04
I38: 16 | J38: =ROUND(J37+$J$23,-3) -> 160000 | K38: =ROUND(K37+$K$23,-3) -> 240000 | L38: =ROUND(L37+$L$23,-3) -> 400000 | M38: =ROUND(M37+$M$23,-3) -> 432000 | N38: =ROUND(N37+$N$23,-3) -> 464000 | O38: =ROUND(O37+$O$23,-3) -> 496000 | Q38: 3 | R38: 0.06
I39: 17 | J39: =ROUND(J38+$J$23,-3) -> 170000 | K39: =ROUND(K38+$K$23,-3) -> 255000 | L39: =ROUND(L38+$L$23,-3) -> 425000 | M39: =ROUND(M38+$M$23,-3) -> 459000 | N39: =ROUND(N38+$N$23,-3) -> 493000 | O39: =ROUND(O38+$O$23,-3) -> 527000 | Q39: 4 | R39: 0.08
I40: 18 | J40: =ROUND(J39+$J$23,-3) -> 180000 | K40: =ROUND(K39+$K$23,-3) -> 270000 | L40: =ROUND(L39+$L$23,-3) -> 450000 | M40: =ROUND(M39+$M$23,-3) -> 486000 | N40: =ROUND(N39+$N$23,-3) -> 522000 | O40: =ROUND(O39+$O$23,-3) -> 558000 | Q40: 5 | R40: 0.1
I41: 20 | J41: =ROUND(#REF!+$J$23,-3) -> #REF! | K41: =ROUND(#REF!+$K$23,-3) -> #REF! | L41: =ROUND(#REF!+$L$23,-3) -> #REF! | M41: =ROUND(#REF!+$M$23,-3) -> #REF! | N41: =ROUND(#REF!+$N$23,-3) -> #REF! | O41: =ROUND(#REF!+$O$23,-3) -> #REF! | Q41: 7 | R41: 0.14
I42: 21 | J42: =ROUND(J41+$J$23,-3) -> #REF! | K42: =ROUND(K41+$K$23,-3) -> #REF! | L42: =ROUND(L41+$L$23,-3) -> #REF! | M42: =ROUND(M41+$M$23,-3) -> #REF! | N42: =ROUND(N41+$N$23,-3) -> #REF! | O42: =ROUND(O41+$O$23,-3) -> #REF! | Q42: 8 | R42: 0.16
I43: 22 | J43: =ROUND(J42+$J$23,-3) -> #REF! | K43: =ROUND(K42+$K$23,-3) -> #REF! | L43: =ROUND(L42+$L$23,-3) -> #REF! | M43: =ROUND(M42+$M$23,-3) -> #REF! | N43: =ROUND(N42+$N$23,-3) -> #REF! | O43: =ROUND(O42+$O$23,-3) -> #REF! | Q43: 9 | R43: 0.18
I44: 23 | J44: =ROUND(J43+$J$23,-3) -> #REF! | K44: =ROUND(K43+$K$23,-3) -> #REF! | L44: =ROUND(L43+$L$23,-3) -> #REF! | M44: =ROUND(M43+$M$23,-3) -> #REF! | N44: =ROUND(N43+$N$23,-3) -> #REF! | O44: =ROUND(O43+$O$23,-3) -> #REF! | Q44: 10 | R44: 0.2
I45: 24 | J45: =ROUND(J44+$J$23,-3) -> #REF! | K45: =ROUND(K44+$K$23,-3) -> #REF! | L45: =ROUND(L44+$L$23,-3) -> #REF! | M45: =ROUND(M44+$M$23,-3) -> #REF! | N45: =ROUND(N44+$N$23,-3) -> #REF! | O45: =ROUND(O44+$O$23,-3) -> #REF! | Q45: 11 | R45: 0.22
...

Sheet IB
A1: Berechnungen für IB-Protokoll
A3: Anpassungen durch den Nutzer
A4: Angaben für das Protokoll | E4: Variante 1 | F4: Variante 2 | G4: Variante 3 | H4: Variante 4 | I4: Variante 5 | J4: Variante 6 | K4: Variante 7 | L4: Variante 8 | M4: Variante 9 | Q4: Stand 1. Januar 2025 Stadt Zürich (E360, EWZ) | S4: Werte anhand Tool IB MFH
A5: Energieverbrauch | B5: =Energie_EBF!K23 -> 4.3 | C5: =Energie_EBF!K12 -> 10000 | D5: kWh/a | E5: Öl (IST-Zustand) | F5: Gas (IST-Zustand) | G5: Öl mit Solarthermie | H5: Gas mit Solarthermie | I5: Luft/Wasser WP | J5: WP mit EWS | K5: Elektroheizung (IST-Zustand) | L5: Fernwärme | O5: Energiequelle | P5: JAZ/η (NEU) | Q5: Energiekosten/kWh | R5: Kosten/kWh Nutzenergie | S5: CO2-Gesetz | T5: CO2 KBOB 2022
A6: Nutzwärmebarf | C6: =Energie_EBF!K15 -> 9000 | D6: kWh/a | O6: Öl | P6: 0.95 | Q6: 0.1 | R6: =Q6/P6 -> 0.10526316 | S6: 0.265 | T6: 0.324
A7: Nutzwärmebarf mit Solar | C7: =C6-'Kosten HLK'!S21*1000*0.6 -> 6600 | D7: kWh/a | O7: Erdgas | P7: 0.95 | Q7: 0.14 | R7: =Q7/P7 -> 0.14736842 | S7: 0.203 | T7: 0.23
A8: Kalkulationszinssatz | C8: 0.02 | O8: Strom L/W | P8: 3 | Q8: 0.25 | R8: =Q8/P8 -> 0.083333333 | S8: 0 | T8: 0.125
A9: Mittl. Abschreibungsdauer | E9: 20 | F9: 20 | G9: 20 | H9: 20 | I9: 25 | J9: 35 | K9: 0 | L9: 35 | M9: 0 | O9: Strom ES | P9: 4 | Q9: 0.25 | R9: =Q9/P9 -> 0.0625 | S9: 0 | T9: 0.125
A10: Annuitätsfaktor | E10: =IFERROR(((1+$C$8)^E9*($C$8))/((1+$C$8)^E9-1),"-") -> 0.061156718 | F10: =IFERROR(((1+$C$8)^F9*($C$8))/((1+$C$8)^F9-1),"-") -> 0.061156718 | G10: =IFERROR(((1+$C$8)^G9*($C$8))/((1+$C$8)^G9-1),"-") -> 0.061156718 | H10: =IFERROR(((1+$C$8)^H9*($C$8))/((1+$C$8)^H9-1),"-") -> 0.061156718 | I10: =IFERROR(((1+$C$8)^I9*($C$8))/((1+$C$8)^I9-1),"-") -> 0.051220438 | J10: =IFERROR(((1+$C$8)^J9*($C$8))/((1+$C$8)^J9-1),"-") -> 0.040002209 | K10: 0 | L10: =IFERROR(((1+$C$8)^L9*($C$8))/((1+$C$8)^L9-1),"-") -> 0.040002209 | M10: =IFERROR(((1+$C$8)^M9*($C$8))/((1+$C$8)^M9-1),"-") -> - | O10: Strom WPBoiler | P10: 3 | Q10: 0.2 | R10: =Q10/P10 -> 0.066666667 | S10: 0 | T10: 0.102
O11: Solarthemie | P11: 80 | Q11: 0.25 | R11: =Q11/P11 -> 0.003125 | S11: 0 | T11: 0.015
A12: Investitionskosten Total (inkl. Solarthermie V. 3+4) | E12: ='Kosten HLK'!B9 -> 15000 | F12: ='Kosten HLK'!B10 -> 12000 | G12: ='Kosten HLK'!B9+'Kosten HLK'!S25 -> 30000 | H12: ='Kosten HLK'!B10+'Kosten HLK'!S25 -> 27000 | I12: ='Kosten HLK'!B6 -> 45000 | J12: ='Kosten HLK'!B7 -> 55000 | K12: 0 | L12: ='Kosten HLK'!B12 -> 46000 | O12: Pellet | P12: 0.9 | Q12: 0.09 | R12: =Q12/P12 -> 0.1 | S12: 0 | T12: 0.028
A13: Abzug Fördergelder (bei Stadt Zürich manuell anpassen) | I13: ='Kosten HLK'!G6 -> 2900 | J13: ='Kosten HLK'!G7 -> 6800 | K13: 0 | L13: ='Kosten HLK'!G12 -> 5200 | O13: Schnitzel | P13: 0.85 | S13: 0 | T13: 0.011
A14: Investitionskosten nach Abzug Fördergelder | E14: =E12-E13 -> 15000 | F14: =F12-F13 -> 12000 | G14: =G12-G13 -> 30000 | H14: =H12-H13 -> 27000 | I14: =I12-I13 -> 42100 | J14: =J12-J13 -> 48200 | K14: 0 | L14: =L12-L13 -> 40800 | M14: =M12-M13 -> 0 | O14: Biogas Stadt Zürich | P14: 0.95 | Q14: 0.19 | R14: =Q14*P14 -> 0.1805 | S14: 0 | T14: 0.124
A15: Kapitalkosten | E15: =IFERROR(ROUND(E12*E10,-2),"-") -> 900 | F15: =IFERROR(ROUND(F12*F10,-2),"-") -> 700 | G15: =IFERROR(ROUND(G12*G10,-2),"-") -> 1800 | H15: =IFERROR(ROUND(H12*H10,-2),"-") -> 1700 | I15: =IFERROR(ROUND(I14*I10,-2),"-") -> 2200 | J15: =IFERROR(ROUND(J14*J10,-2),"-") -> 1900 | K15: =IFERROR(ROUND(K12*K10,-2),"-") -> 0 | L15: =IFERROR(ROUND(L14*L10,-2),"-") -> 1600 | M15: =IFERROR(ROUND(M14*M10,-2),"-") -> - | O15: Fernwärme Züri Oberland | P15: 1 | Q15: 0.2 | R15: =Q15*P15 -> 0.2 | S15: 0 | T15: bei jeder Fernwärme unterschiedlich, immer separt schauen
A16: Energiekosten | E16: =C5*Q6 -> 1000 | F16: =C5*Q7 -> 1400 | G16: =C7*R6 -> 694.73684 | H16: =C7*R7 -> 972.63158 | I16: =C6*R8 -> 750 | J16: =R9*C6 -> 562.5 | K16: =C5*R17 -> 2631.5789 | L16: =C6*R15 -> 1800 | M16: =U9*F6 -> 0 | O16: Fernwärme Stadt Zürich | P16: 1 | Q16: 0.12 | R16: =Q16*P16 -> 0.12 | U16: dazu kommt der Leistungspreis 34.-/kW
A17: Unterhaltskosten | E17: =ROUND(600+20*'Kosten HLK'!R21,-2) -> 600 | F17: =ROUND(600+20*'Kosten HLK'!R21,-2) -> 600 | G17: =ROUND(600+100+20*'Kosten HLK'!S21,-2) -> 800 | H17: =ROUND(600+100+20*'Kosten HLK'!S21,-2) -> 800 | I17: 300 | J17: 200 | K17: 0 | L17: 100 | M17: 200 | O17: Elektroheizung | P17: 0.95 | Q17: 0.25 | R17: =Q17/P17 -> 0.26315789 | S17: 0 | T17: 0.125
A18: Jahreskosten OHNE Kaptialkosten | E18: =ROUND(SUM(E16:E17),-2) -> 1600 | F18: =ROUND(SUM(F16:F17),-2) -> 2000 | G18: =ROUND(SUM(G16:G17),-2) -> 1500 | H18: =ROUND(SUM(H16:H17),-2) -> 1800 | I18: =ROUND(SUM(I16:I17),-2) -> 1100 | J18: =ROUND(SUM(J16:J17),-2) -> 800 | K18: =ROUND(SUM(K16:K17),-2) -> 2600 | L18: =ROUND(SUM(L16:L17),-2) -> 1900 | M18: =ROUND(SUM(M16:M17),-2) -> 200
A20: Platzierung
A21: Kapitalkosten (Annuität) | D21: CHF*20a | E21: =IFERROR(E15*20,"-") -> 18000 | F21: =IFERROR(F15*20,"-") -> 14000 | G21: =IFERROR(G15*20,"-") -> 36000 | H21: =IFERROR(H15*20,"-") -> 34000 | I21: =IFERROR(I15*20,"-") -> 44000 | J21: =IFERROR(J15*20,"-") -> 38000 | K21: =IFERROR(K15*20,"-") -> 0 | L21: =IFERROR(L15*20,"-") -> 32000 | M21: =IFERROR(M15*20,"-") -> -
A22: Energiekosten | D22: CHF*20a | E22: =IFERROR(E16*20,"-") -> 20000 | F22: =IFERROR(F16*20,"-") -> 28000 | G22: =IFERROR(G16*20,"-") -> 13894.737 | H22: =IFERROR(H16*20,"-") -> 19452.632 | I22: =IFERROR(I16*20,"-") -> 15000 | J22: =IFERROR(J16*20,"-") -> 11250 | K22: =IFERROR(K16*20,"-") -> 52631.579 | L22: =IFERROR(L16*20,"-") -> 36000 | M22: =IFERROR(M16*20,"-") -> 0
A23: Unterhaltskosten (Wartung, Rep. etc.) | D23: CHF*20a | E23: =IFERROR(E17*20,"-") -> 12000 | F23: =IFERROR(F17*20,"-") -> 12000 | G23: =IFERROR(G17*20,"-") -> 16000 | H23: =IFERROR(H17*20,"-") -> 16000 | I23: =IFERROR(I17*20,"-") -> 6000 | J23: =IFERROR(J17*20,"-") -> 4000 | K23: =IFERROR(K17*20,"-") -> 0 | L23: =IFERROR(L17*20,"-") -> 2000 | M23: =IFERROR(M17*20,"-") -> 4000
A24: Laufende Kosten über 20 Jahre | D24: CHF*20a | E24: =ROUND(SUM(E21:E23),-3) -> 50000 | F24: =ROUND(SUM(F21:F23),-3) -> 54000 | G24: =ROUND(SUM(G21:G23),-3) -> 66000 | H24: =ROUND(SUM(H21:H23),-3) -> 69000 | I24: =ROUND(SUM(I21:I23),-3) -> 65000 | J24: =ROUND(SUM(J21:J23),-3) -> 53000 | K24: =ROUND(SUM(K21:K23),-3) -> 53000 | L24: =ROUND(SUM(L21:L23),-3) -> 70000 | M24: =ROUND(SUM(M21:M23),-3) -> 4000
A26: Umweltbelstung im Betrieb
A27: CO₂-Emissionen inkl. vorgelagerte Prozesse und unter Verwendung des Schweizer Strommixes (KBOB) (nur als Info wird im IB nicht verwendet) | E27: =C5*T6 -> 3240 | F27: =C5*T7 -> 2300 | G27: =C7*T6 -> 2138.4 | H27: =C7*T7 -> 1518 | I27: =C6*T8/P8 -> 375 | J27: =C6*T9/P9 -> 281.25 | K27: =C6*T17/P17 -> 1184.2105 | M27: =F6*W9/S9 -> #DIV/0!
A28: CO₂-Emissionen gemäss CO₂-Gesetz nach Territorialitätsprinzip ohne vorgelagerte Prozesse (CO2-Gesetz) | E28: =C5*S6 -> 2650 | F28: =C5*S7 -> 2030 | G28: =C7*S6 -> 1749 | H28: =C7*S7 -> 1339.8 | I28: 0 | J28: 0 | K28: 0 | L28: 0 | M28: 0
A31: Einsparungen WP vs. Fossil (CO2-Gesetz) (im Protokoll verwenden) | E31: =ROUND(E28,-2) -> 2700 | F31: =ROUND(F28,-2) -> 2000 | G31: =ROUND(G28,-2) -> 1700 | H31: =ROUND(H28,-2) -> 1300 | K31: In IB nur Energiekosten rechnen mit Hinweis ohne Investitionskosten

Sheet Wirtschaftlichkeit Geb.
B1: Wirtschaftlichkeit | K1: (nur für internen Gebrauch)
B2: Einsparung pro Jahr | K2: Preis der | N2: Preis der | P2: Preis für eine kWh fossil (Standard 7 Rp.) | R2: 0.07
B3: Qt | C3: U | D3: A | E3: HGT | F3: Umrechn. | G3: Einspar. | H3: Inves.-kosten | I3: Annuität | J3: Kosten | K3: Einsp. | M3: CHF/kWh | N3: Einsparung Total | P3: für Berechnung Einsparung Total
B4: kWh | C4: W/m2K | D4: m2 | E4: Kd | G4: kWh/a | H4: CHF | J4: CHF/a | K4: CHF/kWh | L4: % der Ko. angerech. | N4: CHF
B5: Kellerboden | D5: 1
A6: vorher | B6: =C6*D6*E6*F6 -> 230.4 | C6: 3 | D6: =D5 -> 1 | E6: 3200 | F6: =24/1000 -> 0.024
A7: nachher | B7: =C7*D7*E7*F7 -> 19.2 | C7: 0.25 | D7: =D5 -> 1 | E7: 3200 | F7: =24/1000 -> 0.024 | G7: =B6-B7 -> 211.2 | H7: =C67*D5 -> 200 | I7: =B$56 -> 0.048 | J7: =H7*I7 -> 9.6 | K7: =J7/G7 -> 0.045454545 | L7: 1 | M7: =J7/G7*L7 -> 0.045454545 | N7: =ROUND(G7*$R$2,-1) -> 10
B8: Kellerdecke | D8: 1
A9: vorher | B9: =C9*D9*E9*F9 -> 153.6 | C9: 2 | D9: =D8 -> 1 | E9: 3200 | F9: =24/1000 -> 0.024
A10: nachher | B10: =C10*D10*E10*F10 -> 19.2 | C10: 0.25 | D10: =D8 -> 1 | E10: 3200 | F10: =24/1000 -> 0.024 | G10: =B9-B10 -> 134.4 | H10: =C68*D8 -> 150 | I10: =B$56 -> 0.048 | J10: =H10*I10 -> 7.2 | K10: =J10/G10 -> 0.053571429 | L10: 1 | M10: =J10/G10*L10 -> 0.053571429 | N10: =ROUND(G10*$R$2,-1) -> 10
B11: Kellerwände | D11: 1
A12: vorher | B12: =C12*D12*E12*F12 -> 153.6 | C12: 2 | D12: =D11 -> 1 | E12: 3200 | F12: =24/1000 -> 0.024
A13: nachher | B13: =C13*D13*E13*F13 -> 19.2 | C13: 0.25 | D13: =D11 -> 1 | E13: 3200 | F13: =24/1000 -> 0.024 | G13: =B12-B13 -> 134.4 | H13: =C69*D11 -> 150 | I13: =B$56 -> 0.048 | J13: =H13*I13 -> 7.2 | K13: =J13/G13 -> 0.053571429 | L13: 1 | M13: =J13/G13*L13 -> 0.053571429 | N13: =ROUND(G13*$R$2,-1) -> 10
B14: Fenster | D14: 1
A15: vorher | B15: =C15*D15*E15*F15 -> 239.76 | C15: 2.7 | D15: =D14 -> 1 | E15: 3700 | F15: =24/1000 -> 0.024
A16: nachher | B16: =C16*D16*E16*F16 -> 79.92 | C16: 0.9 | D16: =D14 -> 1 | E16: 3700 | F16: =24/1000 -> 0.024 | G16: =B15-B16 -> 159.84 | H16: =C77*D14 -> 950 | I16: =B$56 -> 0.048 | J16: =H16*I16 -> 45.6 | K16: =J16/G16 -> 0.28528529 | L16: 0.3 | M16: =J16/G16*L16 -> 0.085585586 | N16: =ROUND(G16*$R$2,-1) -> 10
B17: Solar | D17: 1
A18: vorher | B18: -
A19: nachher | B19: (knapp dimensioniert) | G19: =L80*D17 -> 450 | H19: =ROUND(D17*D80+I80,-2) -> 10800 | I19: =B53 -> 0.054275921 | J19: =H19*I19 -> 586.17995 | K19: =J19/G19 -> 1.3026221 | L19: 1 | M19: =J19/G19*L19 -> 1.3026221 | N19: =ROUND(G19*$R$2,-1) -> 30
A20: Storenkasten mit 2cm Aerogel | D20: 1
A21: vorher | B21: =C21*D21*E21*F21 -> 133.812 | C21: 1.5 | D21: =D20 -> 1 | E21: 3717 | F21: =24/1000 -> 0.024
A22: nachher | B22: =C22*D22*E22*F22 -> 41.92776 | C22: 0.47 | D22: =D20 -> 1 | E22: 3717 | F22: =24/1000 -> 0.024 | G22: =B21-B22 -> 91.88424 | H22: =C66*D20 -> 300 | I22: =B$56 -> 0.048 | J22: =H22*I22 -> 14.4 | K22: =J22/G22 -> 0.15671893 | L22: 1 | M22: =J22/G22*L22 -> 0.15671893 | N22: =ROUND(G22*$R$2,-1) -> 10
B23: Estrichboden | D23: 1
A24: vorher | B24: =C24*D24*E24*F24 -> 178.416 | C24: 2 | D24: =D23 -> 1 | E24: 3717 | F24: =24/1000 -> 0.024
A25: nachher | B25: =C25*D25*E25*F25 -> 22.302 | C25: 0.25 | D25: =D23 -> 1 | E25: 3717 | F25: =24/1000 -> 0.024 | G25: =B24-B25 -> 156.114 | H25: =C65*D23 -> 150 | I25: =B$56 -> 0.048 | J25: =H25*I25 -> 7.2 | K25: =J25/G25 -> 0.046120143 | L25: 1 | M25: =J25/G25*L25 -> 0.046120143 | N25: =ROUND(G25*$R$2,-1) -> 10
B26: Dach | D26: 1
A27: vorher | B27: =C27*D27*E27*F27 -> 356.832 | C27: 4 | D27: =D26 -> 1 | E27: 3717 | F27: =24/1000 -> 0.024
A28: nachher | B28: =C28*D28*E28*F28 -> 17.8416 | C28: 0.2 | D28: =D26 -> 1 | E28: 3717 | F28: =24/1000 -> 0.024 | G28: =B27-B28 -> 338.9904 | H28: =C73*D26 -> 210 | I28: =B$56 -> 0.048 | J28: =H28*I28 -> 10.08 | K28: =J28/G28 -> 0.029735355 | L28: 0.3 | M28: =J28/G28*L28 -> 0.0089206066 | N28: =ROUND(G28*$R$2,-1) -> 20
B29: Aussen-Wand | D29: 1
A30: vorher | B30: =C30*D30*E30*F30 -> 98.1288 | C30: 1.1 | D30: =D29 -> 1 | E30: 3717 | F30: =24/1000 -> 0.024
A31: nachher | B31: =C31*D31*E31*F31 -> 17.8416 | C31: 0.2 | D31: =D29 -> 1 | E31: 3717 | F31: =24/1000 -> 0.024 | G31: =B30-B31 -> 80.2872 | H31: =D79*D29 -> 300 | I31: =B$56 -> 0.048 | J31: =H31*I31 -> 14.4 | K31: =J31/G31 -> 0.17935611 | L31: 0.3 | M31: =J31/G31*L31 -> 0.053806833 | N31: =ROUND(G31*$R$2,-1) -> 10
B32: Komfortlüftung | C32: m3/h | D32: 1 | E32: EBF
A33: vorher | B33: =C33*E33*F33*D33 -> 19.9479 | C33: 0.7 | D33: =D32 -> 1 | E33: 3717 | F33: =24*1.15/1000/3.6 -> 0.0076666667
A34: nachher | B34: =C34*E34*F34*D34 -> 8.5491 | C34: =0.1+(0.2*1) -> 0.3 | D34: =D32 -> 1 | E34: 3717 | F34: =24*1.15/1000/3.6 -> 0.0076666667 | G34: =B33-B34 -> 11.3988 | H34: =C81*D32 -> 100 | I34: =B$56 -> 0.048 | J34: =H34*I34 -> 4.8 | K34: =J34/G34 -> 0.42109696 | L34: 0.5 | M34: =J34/G34*L34 -> 0.21054848 | N34: =ROUND(G34*R2,-1) -> 0
A36: Heizung
B37: Wärmepumpe | D37: Kosten Strom/kWh | F37: 0.14 | H37: Kosten fossil/kWh | J37: 0.09
A38: vorher | B38: 20000 | E38: COP | F38: 4 | G38: Ist abhängig von VL-Temp., und ES-WP oder Luft-WP
A39: nacher | B39: =B38/F38 -> 5000 | G39: =B38-B39 -> 15000 | H39: Siehe Tabelle | N39: =ROUND(G39*J37-B39*(F37-J37),-2) -> 1100
B40: Pellet | D40: Kosten Pellet/kWh | F40: 0.07 | H40: Kosten fossil/kWh | J40: =J37 -> 0.09
A41: vorher | B41: =B38 -> 20000 | D41: Effizenzsteigerung | F41: 0.1 | O41: Die Kosten der Heizung befindet sich im Tabellenbalt "Kosten Heizung Grafik (JS)"
...

Sheet HGT
A1: Heizgradtage (HGT)
A2: Klimastation | C2: Zürich-SMA
C3: Mitelwert
A4: Kalenderjahr | C4: 2011 bis 2020 | D4: 2014 | E4: 2015 | F4: 2016 | G4: 2017 | H4: 2018 | I4: 2019 | J4: 2020 | K4: 2021 | L4: 2022 | M4: 2023 | N4: 2024 | O4: 2025 | P4: 2026
A5: HGT Kalenderjahr | B5: =Energie_EBF!K23 -> 4.3 | C5: 3124.7 | D5: 2784 | E5: 3060 | F5: 3335 | G5: 3231 | H5: 2935 | I5: 3112 | J5: 2933 | K5: 3401 | L5: 2775 | M5: 2907 | N5: 2874 | O5: 3066 | P5: 0
A6: Korrekturfaktor | C6: Kalenderjahr | D6: 1.1223779 | E6: 1.0211438 | F6: 0.93694153 | G6: 0.96709997 | H6: 1.0646337 | I6: 1.004081 | J6: 1.0653597 | K6: 0.91875919 | L6: 1.126018 | M6: 1.0748882 | N6: 1.0872303 | O6: 1.0191455 | P6: 1
A9: https://www.hev-schweiz.ch/vermieten/nebenkostenabrechnungen/heizgradtage
A11: HGT-Faktoren senkrecht
A13: 2014 | B13: 1.1223779
A14: 2015 | B14: 1.0211438
A15: 2016 | B15: 0.93694153
A16: 2017 | B16: 0.96709997
A17: 2018 | B17: 1.0646337
A18: 2019 | B18: 1.004081
A19: 2020 | B19: 1.0653597
A20: 2021 | B20: 0.91875919
A21: 2022 | B21: 1.126018
A22: 2023 | B22: 1.0748882
A23: 2024 | B23: 1.0872303
A24: 2025 | B24: 1.0191455

Sheet Umrechnungsfaktoren

Sheet Solarthermie

Sheet Kosten PVA
B1: Wirtschaftlichkeitsberechnung für PVA (Indach bis 30 kWp) | N1: Stand | O1: 44672 | P1: JS
B3: =Energie_EBF!#REF! -> #REF! | I3: Gelbe Felder bearbeiten
B4: Grösse der Anlage [m2] | N4: Kosten Aufdach PVA | R4: Kosten Indach PVA
C5: Dachfläche | D5: Abzüge (Kamin, Lüftung, etc.) | E5: Nutzbare Dachfläche | N5: kWp | O5: Aufdach | P5: CHF/ kWp | R5: kWp | S5: Indach | T5: CHF/ kWp
B6: Bsp. | C6: 82 | D6: 20 | E6: =C6-D6 -> 62 | N6: 3 | O6: =ROUND(P6*N6,-2) -> 10500 | P6: 3500 | R6: 3 | S6: =ROUND(T6*R6,-2) -> 16800 | T6: =P6*1.6 -> 5600
B7: =B3 -> #REF! | C7: 44 | D7: 0 | E7: =C7-D7 -> 44 | N7: 4 | O7: =ROUND(P7*N7,-2) -> 13800 | P7: =ROUND(P6*0.985,-1) -> 3450 | R7: 4 | S7: =ROUND(T7*R7,-3) -> 22000 | T7: =ROUND(T6*0.98,-1) -> 5490
N8: 5 | O8: =ROUND(P8*N8,-2) -> 17000 | P8: =ROUND(P7*0.985,-1) -> 3400 | R8: 5 | S8: =ROUND(T8*R8,-3) -> 27000 | T8: =ROUND(T7*0.98,-1) -> 5380
B9: Anlage Daten | N9: 6 | O9: =ROUND(P9*N9,-2) -> 20000 | P9: =ROUND(P8*0.983,-1) -> 3340 | R9: 6 | S9: =ROUND(T9*R9,-3) -> 32000 | T9: =ROUND(T8*0.98,-1) -> 5270
B10: System | F10: Aufdach | N10: 7 | O10: =ROUND(P10*N10,-2) -> 23000 | P10: =ROUND(P9*0.983,-1) -> 3280 | R10: 7 | S10: =ROUND(T10*R10,-3) -> 36000 | T10: =ROUND(T9*0.98,-1) -> 5160
B11: Ausrichtung | F11: Süden | N11: 8 | O11: =ROUND(P11*N11,-2) -> 25800 | P11: =ROUND(P10*0.983,-1) -> 3220 | R11: 8 | S11: =ROUND(T11*R11,-3) -> 40000 | T11: =ROUND(T10*0.98,-1) -> 5060
B12: Anlage in Uster | F12: Ja | I12: Anlage in Stadt Zürich | N12: 9 | O12: =ROUND(P12*N12,-2) -> 28500 | P12: =ROUND(P11*0.983,-1) -> 3170 | R12: 9 | S12: =ROUND(T12*R12,-3) -> 45000 | T12: =ROUND(T11*0.98,-1) -> 4960
B13: Grösse | E13: kWp | F13: =ROUND(E7/4.5,1) -> 9.8 | I13: https://rechner.energie-foerderung.ch/zs | N13: 10 | O13: =ROUND(P13*N13,-2) -> 31200 | P13: =ROUND(P12*0.983,-1) -> 3120 | R13: 10 | S13: =ROUND(T13*R13,-3) -> 49000 | T13: =ROUND(T12*0.98,-1) -> 4860
B14: Ertrag der Anlage | E14: kWh/a | F14: =ROUND(IF(F11="Süden",1000,900)*F13,-2) -> 9800 | N14: 11 | O14: =ROUND(P14*N14,-2) -> 33800 | P14: =ROUND(P13*0.983,-1) -> 3070 | R14: 11 | S14: =ROUND(T14*R14,-3) -> 52000 | T14: =ROUND(T13*0.98,-1) -> 4760
B15: Anlagekosten | F15: =INDEX(N5:T193,F13-1,IF(F10="Indach",6,2)) -> 28500 | N15: 12 | O15: =ROUND(P15*N15,-2) -> 36200 | P15: =ROUND(P14*0.983,-1) -> 3020 | R15: 12 | S15: =ROUND(T15*R15,-3) -> 56000 | T15: =ROUND(T14*0.98,-1) -> 4660
B16: =IF(AND(F10="Indach",F13>30),"!!!ACHTUNG INDACHANLAGE > 30 kWp KANN NICHT BERECHNET WERDEN!!!","") | N16: 13 | O16: =ROUND(P16*N16,-2) -> 38600 | P16: =ROUND(P15*0.983,-1) -> 2970 | R16: 13 | S16: =ROUND(T16*R16,-3) -> 59000 | T16: =ROUND(T15*0.98,-1) -> 4570
B17: Fördergelder 2019 | I17: Ertrag (aus Eigennutzung und Einspeisung) | N17: 14 | O17: =ROUND(P17*N17,-2) -> 40900 | P17: =ROUND(P16*0.983,-1) -> 2920 | R17: 14 | S17: =ROUND(T17*R17,-3) -> 63000 | T17: =ROUND(T16*0.98,-1) -> 4480
D18: CHF/kWp | E18: kWp | N18: 15 | O18: =ROUND(P18*N18,-2) -> 43100 | P18: =ROUND(P17*0.983,-1) -> 2870 | R18: 15 | S18: =ROUND(T18*R18,-3) -> 66000 | T18: =ROUND(T17*0.98,-1) -> 4390
B19: EIV Grundbetrag | D19: 350 | E19: 1 | F19: =D19*E19 -> 350 | I19: Eigenstromanteil (Standard 20-30% EFH) | N19: 16 | O19: =ROUND(P19*N19,-2) -> 45100 | P19: =ROUND(P18*0.983,-1) -> 2820 | R19: 16 | S19: =ROUND(T19*R19,-3) -> 69000 | T19: =ROUND(T18*0.98,-1) -> 4300
B20: EIV Leistungsbetragbis 30 kW | D20: =IF(F10=V32,(IF(E20<=30,Y32,Z32)),IF(E20<=30,Y33,Z33)) -> 380 | E20: =IF(F13>29,30,F13) -> 9.8 | F20: =D20*E20 -> 3724 | J20: Eigennutzung | K20: Einspeisung | L20: Ertrag | N20: 17 | O20: =ROUND(P20*N20,-2) -> 47100 | P20: =ROUND(P19*0.983,-1) -> 2770 | R20: 17 | S20: =ROUND(T20*R20,-3) -> 72000 | T20: =ROUND(T19*0.98,-1) -> 4210
B21: EIV Leistungsbetrag ab 30 kW | D21: =IF(F10=V32,(IF(E21>=30,Y32,Z32)),IF(E21<=30,Y33,Z33)) -> 380 | E21: =IF(F13>29,F13-E20,"-") -> - | F21: =IFERROR(D21*E21,"-") -> - | I21: Eigenstromanteil | J21: 0.2 | K21: =1-J21 -> 0.8 | N21: 18 | O21: =ROUND(P21*N21,-2) -> 49000 | P21: =ROUND(P20*0.983,-1) -> 2720 | R21: 18 | S21: =ROUND(T21*R21,-3) -> 74000 | T21: =ROUND(T20*0.98,-1) -> 4130
B22: Ökofonds Uster | D22: =IF(F12="Ja",500,0) -> 500 | E22: =IF(F12="Ja",F13,0) -> 9.8 | F22: =IF((D22*E22)<=30000,D22*E22,30000) -> 4900 | H22: max 30'000 | I22: HT | J22: 0.19 | K22: =0.055+0.023 -> 0.078 | L22: =J22*$J$21+K22*$K$21 -> 0.1004 | N22: 19 | O22: =ROUND(P22*N22,-2) -> 50700 | P22: =ROUND(P21*0.983,-1) -> 2670 | R22: 19 | S22: =ROUND(T22*R22,-3) -> 77000 | T22: =ROUND(T21*0.98,-1) -> 4050
B23: weitere Fördergelder | I23: NT | J23: 0.12 | K23: =0.045+0.023 -> 0.068 | L23: =J23*$J$21+K23*$K$21 -> 0.0784 | N23: 20 | O23: =ROUND(P23*N23,-2) -> 52400 | P23: =ROUND(P22*0.983,-1) -> 2620 | R23: 20 | S23: =ROUND(T23*R23,-3) -> 79000 | T23: =ROUND(T22*0.98,-1) -> 3970
B24: Total Förderbeiträge | F24: =SUM(F19:F23) -> 8974 | I24: Mischtarif | J24: =J22*11/14+J23*3/14 -> 0.175 | K24: =K22*11/14+K23*3/14 -> 0.075857143 | L24: =J24*$J$21+K24*$K$21 -> 0.095685714 | N24: 21 | O24: =ROUND(P24*N24,-2) -> 54200 | P24: =ROUND(P23*0.983,-1) -> 2580 | R24: 21 | S24: =ROUND(T24*R24,-3) -> 82000 | T24: =ROUND(T23*0.98,-1) -> 3890
I25: (Energiepreise Energie Uster) | K25: inkl. HKN | N25: 22 | O25: =ROUND(P25*N25,-2) -> 55900 | P25: =ROUND(P24*0.983,-1) -> 2540 | R25: 22 | S25: =ROUND(T25*R25,-3) -> 84000 | T25: =ROUND(T24*0.98,-1) -> 3810
B26: Nettoinvestitionskosten netto | F26: =F15-F24 -> 19526 | N26: 23 | O26: =ROUND(P26*N26,-2) -> 57500 | P26: =ROUND(P25*0.983,-1) -> 2500 | R26: 23 | S26: =ROUND(T26*R26,-3) -> 86000 | T26: =ROUND(T25*0.98,-1) -> 3730
N27: 24 | O27: =ROUND(P27*N27,-2) -> 59000 | P27: =ROUND(P26*0.983,-1) -> 2460 | R27: 24 | S27: =ROUND(T27*R27,-3) -> 88000 | T27: =ROUND(T26*0.98,-1) -> 3660
B28: Kapitalkosten und Betriebskosten | N28: 25 | O28: =ROUND(P28*N28,-2) -> 60500 | P28: =ROUND(P27*0.983,-1) -> 2420 | R28: 25 | S28: =ROUND(T28*R28,-3) -> 90000 | T28: =ROUND(T27*0.98,-1) -> 3590
B29: Kapitalkosten Annuität | D29: CHF/Jahr | E29: =IF(D30=0,0,(D30*(1+D30)^D31)/((1+D30)^D31-1)) -> 0.054275921 | F29: =(F15-F24)*E29 -> 1059.7916 | N29: 26 | O29: =ROUND(P29*N29,-2) -> 61900 | P29: =ROUND(P28*0.983,-1) -> 2380 | R29: 26 | S29: =ROUND(T29*R29,-3) -> 92000 | T29: =ROUND(T28*0.98,-1) -> 3520
C30: Durchschnittszins | D30: 0.025 | N30: 27 | O30: =ROUND(P30*N30,-2) -> 63200 | P30: =ROUND(P29*0.983,-1) -> 2340 | R30: 27 | S30: =ROUND(T30*R30,-3) -> 93000 | T30: =ROUND(T29*0.98,-1) -> 3450
C31: Laufzeit | D31: 25 | N31: 28 | O31: =ROUND(P31*N31,-2) -> 64400 | P31: =ROUND(P30*0.983,-1) -> 2300 | R31: 28 | S31: =ROUND(T31*R31,-3) -> 95000 | T31: =ROUND(T30*0.98,-1) -> 3380 | V31: Fördergelder Grundbeitrag | Y31: <30 kWp | Z31: 31-100 kWp
I32: jährliche Betriebskosten | J32: 0.01 | K32: von Investitionskosten | N32: 29 | O32: =ROUND(P32*N32,-2) -> 65500 | P32: =ROUND(P31*0.983,-1) -> 2260 | R32: 29 | S32: =ROUND(T32*R32,-3) -> 96000 | T32: =ROUND(T31*0.98,-1) -> 3310 | V32: Aufdach | X32: 350 | Y32: 380 | Z32: 290
B33: Betriebskosten [CHF/a] | F33: =F15*J32 -> 285 | I33: Die Jährlichen Betriebskosten für Photovoltaikanlagen | N33: 30 | O33: =ROUND(P33*N33,-2) -> 66600 | P33: =ROUND(P32*0.983,-1) -> 2220 | R33: 30 | S33: =ROUND(T33*R33,-3) -> 97000 | T33: =ROUND(T32*0.98,-1) -> 3240 | V33: Indach | X33: 385 | Y33: 420 | Z33: 320
I34: Dabei inbegriffen ist der Ersatz eines WR | N34: 31 | O34: =ROUND(P34*N34,-2) -> 67600 | P34: =ROUND(P33*0.983,-1) -> 2180
B35: Total Jahreskosten | F35: =ROUND(SUM(F29:F34),-2) -> 1300 | N35: 32 | O35: =ROUND(P35*N35,-2) -> 68500 | P35: =ROUND(P34*0.983,-1) -> 2140
H36: vs. | I36: Ertrag aus Eigennutzung und Einspeisung [CHF/kWh] | L36: =L24 -> 0.095685714 | N36: 33 | O36: =ROUND(P36*N36,-2) -> 69300 | P36: =ROUND(P35*0.983,-1) -> 2100 | T36: =2300*30 -> 69000
B37: Gestehungskosten [CHF/kWh] | F37: =F35/F14 -> 0.13265306 | N37: 34 | O37: =ROUND(P37*N37,-2) -> 70000 | P37: =ROUND(P36*0.983,-1) -> 2060 | T37: =2500*30 -> 75000
I38: Anlage ist wirtschaftlich? | L38: =IF(F37<L36,"Ja","Nein") -> Nein | N38: 35 | O38: =ROUND(P38*N38,-2) -> 70700 | P38: =ROUND(P37*0.983,-1) -> 2020
B39: Spezifische Kosten OHNE Fördergelder [CHF/kWp] | F39: =ROUND(F15/F13,-2) -> 2900 | N39: 36 | O39: =ROUND(P39*N39,-2) -> 71600 | P39: =ROUND(P38*0.983,-1) -> 1990
N40: 37 | O40: =ROUND(P40*N40,-2) -> 72500 | P40: =ROUND(P39*0.983,-1) -> 1960
B41: Spezifische Kosten MIT Fördergelder [CHF/kWp] | F41: =ROUND(F26/F13,-2) -> 2000 | N41: 38 | O41: =ROUND(P41*N41,-2) -> 73300 | P41: =ROUND(P40*0.983,-1) -> 1930
...

Sheet Bauteilkatalog
A1: Bauteil | C1: l [W/mK]
A2: - Bauteil wählen -
A3: Aussenputz | C3: 0.87
A4: Blähtonbeton | C4: 0.29
A5: Blähtonbeton | B5: =Energie_EBF!K23 -> 4.3 | C5: 0.5
A6: Blähtonbeton | C6: 1
A7: Bruchstein (Kalkstein) | C7: 1.46
A8: Bruchstein (Sandstein) | C8: 1.34
A9: Bruchsteinmauerwerk | C9: 2.1
A10: Buchenholz | C10: 0.17
A11: Calmo-Backstein | C11: 0.7
A12: Duripanelplatte | C12: 0.26
A13: Durisol-Dachplatte | C13: 0.12
A14: Eichenholz | C14: 0.21
A15: Einsteinmauerwerk | C15: 0.44
A16: Erdmaterial | C16: 2.3
A17: Fichtenholz | C17: 0.14
... A69: Zementüberzug | C69: 1.5
A70: Holzwollenplatte | B70: Bspw. Gargendecke | C70: 0.09
